<?xml version="1.0" ?>
<robot name="WATER" xmlns:xacro="http://www.ros.org/wiki/xacro">

<xacro:include filename="$(find WATER_description)/urdf/materials.xacro" />
<!--<xacro:include filename="$(find WATER_description)/urdf/WATER.trans" />-->
<xacro:include filename="$(find WATER_description)/urdf/WATER.gazebo" />

<!--Base Link/ Boat Hull-->
<link name="base_link">
  <inertial>
    <origin rpy="0 0 0" xyz="0.041985844365174226 0.5041551418509241 0.11753492516942377"/>
    <mass value="100.05"/>
    <inertia ixx="102.253408" ixy="0.944947" ixz="0.571694" iyy="75.226668" iyz="0.019964" izz="175.055626"/>
  </inertial>
  <visual>
    <origin rpy="0 0 0" xyz="0 0 0"/>
    <geometry>
      <mesh filename="package://WATER_description/meshes/base_link.stl" scale="0.001 0.001 0.001"/>
    </geometry>
    <material name="silver"/>
  </visual>
  <collision>
    <origin rpy="0 0 0" xyz="0 0 0"/>
    <geometry>
      <mesh filename="package://WATER_description/meshes/base_link.stl" scale="0.001 0.001 0.001"/>
    </geometry>
  </collision>
</link>

<!--Left Motor Support-->
<link name="motor_support_left_1">
  <inertial>
    <origin rpy="0 0 0" xyz="-0.00038428463028200577 -1.931763642015749e-05 0.2794011308123638"/>
    <mass value="1"/>
    <inertia ixx="0.281164" ixy="-2.4e-05" ixz="0.002165" iyy="0.281586" iyz="-0.0003" izz="0.004869"/>
  </inertial>
  <visual>
    <origin rpy="0 0 0" xyz="0.457043 -0.766899 -0.19"/>
    <geometry>
      <mesh filename="package://WATER_description/meshes/motor_support_left_1.stl" scale="0.001 0.001 0.001"/>
    </geometry>
    <material name="silver"/>
  </visual>
  <collision>
    <origin rpy="0 0 0" xyz="0.457043 -0.766899 -0.19"/>
    <geometry>
      <mesh filename="package://WATER_description/meshes/motor_support_left_1.stl" scale="0.001 0.001 0.001"/>
    </geometry>
  </collision>
</link>

<!--Right Motor Support-->
<link name="motor_support_right_1">
  <inertial>
    <origin rpy="0 0 0" xyz="-0.005187497162707055 0.13542109450750728 0.37290152359449974"/>
    <mass value="1"/>
    <inertia ixx="1.104335" ixy="0.022331" ixz="0.012255" iyy="0.483329" iyz="-0.286828" izz="0.631875"/>
  </inertial>
  <visual>
    <origin rpy="0 0 0" xyz="0.436789 -0.206555 -0.19"/>
    <geometry>
      <mesh filename="package://WATER_description/meshes/motor_support_right_1.stl" scale="0.001 0.001 0.001"/>
    </geometry>
    <material name="silver"/>
  </visual>
  <collision>
    <origin rpy="0 0 0" xyz="0.436789 -0.206555 -0.19"/>
    <geometry>
      <mesh filename="package://WATER_description/meshes/motor_support_right_1.stl" scale="0.001 0.001 0.001"/>
    </geometry>
  </collision>
</link>

<!--Left Propller-->
<link name="propeller_left_1">
  <inertial>
    <origin rpy="0 0 0" xyz="-0.02465138415626883 -3.202893716913735e-07 -5.662137425588298e-15"/>
    <mass value="0.025"/>
    <inertia ixx="0.001968" ixy="-0.0" ixz="0.0" iyy="0.001151" iyz="-0.0" izz="0.001151"/>
  </inertial>
  <visual>
    <origin rpy="0 0 0" xyz="0.497574 -0.206555 -0.715"/>
    <geometry>
      <mesh filename="package://WATER_description/meshes/propeller_left_1.stl" scale="0.001 0.001 0.001"/>
    </geometry>
    <material name="silver"/>
  </visual>
  <collision>
    <origin rpy="0 0 0" xyz="0.497574 -0.206555 -0.715"/>
    <geometry>
      <mesh filename="package://WATER_description/meshes/propeller_left_1.stl" scale="0.001 0.001 0.001"/>
    </geometry>
  </collision>
</link>

<!--Right Propeller-->
<link name="propeller_left_3">
  <inertial>
    <origin rpy="0 0 0" xyz="-0.024651081039449574 8.693535802350993e-08 3.5338152826192015e-07"/>
    <mass value="0.025"/>
    <inertia ixx="0.001968" ixy="0.0" ixz="0.0" iyy="0.001151" iyz="-0.0" izz="0.001151"/>
  </inertial>
  <visual>
    <origin rpy="0 0 0" xyz="0.521155 -0.767824 -0.713099"/>
    <geometry>
      <mesh filename="package://WATER_description/meshes/propeller_left_3.stl" scale="0.001 0.001 0.001"/>
    </geometry>
    <material name="silver"/>
  </visual>
  <collision>
    <origin rpy="0 0 0" xyz="0.521155 -0.767824 -0.713099"/>
    <geometry>
      <mesh filename="package://WATER_description/meshes/propeller_left_3.stl" scale="0.001 0.001 0.001"/>
    </geometry>
  </collision>
</link>

<!--Camera Link-->
<link name="camera_link_1">
  <inertial>
    <origin rpy="0 0 0" xyz="3.962738093221674e-08 -1.2711576602431052e-07 0.025000000000001354"/>
    <mass value="0.05"/>
    <inertia ixx="0.027778" ixy="0.000684" ixz="-0.0" iyy="0.008201" iyz="0.0" izz="0.032708"/>
  </inertial>
  <visual>
    <origin rpy="0 0 0" xyz="0.447271 -0.462171 -0.69"/>
    <geometry>
      <mesh filename="package://WATER_description/meshes/camera_link_1.stl" scale="0.001 0.001 0.001"/>
    </geometry>
    <material name="silver"/>
  </visual>
  <collision>
    <origin rpy="0 0 0" xyz="0.447271 -0.462171 -0.69"/>
    <geometry>
      <mesh filename="package://WATER_description/meshes/camera_link_1.stl" scale="0.001 0.001 0.001"/>
    </geometry>
  </collision>
</link>

<!--Balance Link-->
<link name="balance_1">
  <inertial>
    <origin rpy="0 0 0" xyz="0.024984655377752518 0.0008720125959205127 0.049999999999999184"/>
    <mass value="2.1"/>
    <inertia ixx="0.059224" ixy="0.001711" ixz="0.0" iyy="0.010281" iyz="-0.0" izz="0.053151"/>
  </inertial>
  <visual>
    <origin rpy="0 0 0" xyz="-0.332254 -0.514292 -0.19"/>
    <geometry>
      <mesh filename="package://WATER_description/meshes/balance_1.stl" scale="0.001 0.001 0.001"/>
    </geometry>
    <material name="silver"/>
  </visual>
  <collision>
    <origin rpy="0 0 0" xyz="-0.332254 -0.514292 -0.19"/>
    <geometry>
      <mesh filename="package://WATER_description/meshes/balance_1.stl" scale="0.001 0.001 0.001"/>
    </geometry>
  </collision>
</link>

<!--Left Motor Support Joint-->
<joint name="Rigid16" type="fixed">
  <origin rpy="0 0 0" xyz="-0.457043 0.766899 0.19"/>
  <parent link="base_link"/>
  <child link="motor_support_left_1"/>
</joint>

<!--Right Motor Support Joint-->
<joint name="Rigid17" type="fixed">
  <origin rpy="0 0 0" xyz="-0.436789 0.206555 0.19"/>
  <parent link="base_link"/>
  <child link="motor_support_right_1"/>
</joint>

<!--Left Propller Joint-->
<joint name="Rev18" type="continuous">
  <origin rpy="0 0 0" xyz="-0.064112 0.000925 0.523099"/>
  <parent link="motor_support_left_1"/>
  <child link="propeller_left_1"/>
  <axis xyz="-1.0 0.0 0.0"/>
  <limit effort="300" velocity="10"/>
</joint>

<!--Right Propller Joint-->
<joint name="Rev19" type="continuous">
  <origin rpy="0 0 0" xyz="-0.060785 0.0 0.525"/>
  <parent link="motor_support_right_1"/>
  <child link="propeller_left_3"/>
  <axis xyz="-1.0 0.0 -0.0"/>
  <limit effort="300" velocity="10"/>
</joint>

<!--Camera Joint-->
<joint name="Rigid20" type="fixed">
  <origin rpy="0 0 0" xyz="-0.010482 0.255616 0.5"/>
  <parent link="motor_support_right_1"/>
  <child link="camera_link_1"/>
</joint>

<joint name="Rigid21" type="fixed">
  <origin rpy="0 0 0" xyz="0.332254 0.514292 0.19"/>
  <parent link="base_link"/>
  <child link="balance_1"/>
</joint>

<!--Tranmission for Right Propller-->
<transmission name="simple_trans_right">
  <type>transmission_interface/SimpleTransmission</type>
  <joint name="Rev19">
    <hardwareInterface>hardware_interface/VelocityJointInterface</hardwareInterface>
  </joint>
  <actuator name="Right_propeller_motor">
    <mechanicalReduction>1</mechanicalReduction>
    <hardwareInterface>hardware_interface/VelocityJointInterface</hardwareInterface>
  </actuator>
</transmission>

<!--Tranmission for Left Propller-->
<transmission name="simple_trans_left">
  <type>transmission_interface/SimpleTransmission</type>
  <joint name="Rev18">
    <hardwareInterface>hardware_interface/VelocityJointInterface</hardwareInterface>
  </joint>
  <actuator name="Left_propeller_motor">
    <mechanicalReduction>1</mechanicalReduction>
    <hardwareInterface>hardware_interface/VelocityJointInterface</hardwareInterface>
  </actuator>
</transmission>

</robot>
